<robot name="digit">
    <link name="world"/>

    <link name="ball">
        <visual>
        <origin xyz="0.0 0.0 0.0" rpy="0 0 0" />
        <geometry>
            <sphere radius="0.01"/>
        </geometry>
        <material name="ball_material">
            <color rgba="1.0 0.0 0.0 1.0"/>
        </material>
        </visual>  
        <collision>
        <origin xyz="0.0 0.0 0.0" rpy="0 0 0"/>
        <geometry>
            <sphere radius="0.01"/>
        </geometry>
        </collision>
    </link>
    
    <joint name = "rail" type = "prismatic">
        <parent link="world"/>    
        <child link="ball"/>    
        <origin xyz="0.0 0.0 0.0"/>    
        <axis xyz="0 1 0"/>    
        <limit lower="0.0" upper="0.2"/>    
        <dynamics damping="0.0" friction="0.0"/>  
    </joint>

</robot>
