<robot name="box">
    <link name="world"/>

    <link name="box">
        <visual>
        <origin xyz="0.0 0.009 0.0" rpy="0 0 0" />
        <geometry>
            <mesh filename="../../meshes/cube_14mm.obj"/>
        </geometry>
        <material name="box_material">
            <color rgba="0.0 0.0 1.0 1.0"/>
        </material>
        </visual>  
        <collision>
        <origin xyz="0.0 0.009 0.0" rpy="0 0 0"/>
        <geometry>
            <mesh filename="../../meshes/cube_14mm.obj"/>
        </geometry>
        </collision>
		<inertial>
			<origin rpy="0.0 0.0 0.0" xyz="0.0 -7.28277e-3 0.0"/>
			<mass value="0.00327211"/>
			<inertia ixx="1.14764e-7" iyy="8.89985e-8" izz="1.14738e-7" ixy="0.0" ixz="-4.72875e-14" iyz="0.0"/>
		</inertial>
    </link>
    
    <joint name = "rail" type = "prismatic">
        <parent link="world"/>    
        <child link="box"/>    
        <origin xyz="0.0 0.0 0.0"/>    
        <axis xyz="0 1 0"/>    
        <limit lower="0.0" upper="0.2"/>    
        <dynamics damping="0.0" friction="0.0"/>  
    </joint>

</robot>
