<robot name="digit">
    <link name="world"/>

    <link name="ball">
        <visual>
        <origin xyz="0.0 0.0 -0.2" rpy="0 0 0" />
        <geometry>
            <sphere radius="0.01"/>
        </geometry>
        <material name="ball_material">
            <color rgba="1.0 0.0 0.0 1.0"/>
        </material>
        </visual>  
        <collision>
        <origin xyz="0.0 0.0 -0.2" rpy="0 0 0"/>
        <geometry>
            <sphere radius="0.01"/>
        </geometry>
        </collision>
    </link>
    
    <joint name = "rail" type = "prismatic">
        <parent link="world"/>    
        <child link="ball"/>    
        <origin xyz="0.0 0.0 0.0"/>    
        <axis xyz="0 0 1"/>    
        <limit lower="0.15" upper="0.161"/>    
        <dynamics damping="0.0" friction="0.0"/>  
    </joint>

    <link name="digit_base">
        <visual>
            <origin xyz="-1.7347234759768070944e-18 0.0039999999999999992159 -0.02834999999999999673" rpy="0 -0 0" />
            <geometry>
            <mesh filename="../meshes/digit_bottom.stl"/>
            </geometry>
            <material name="digit_bottom_material">
            <color rgba="0.30196078431372547213 0.30196078431372547213 0.30196078431372547213 1.0"/>
            </material>
        </visual>
        <collision>
            <origin xyz="-1.7347234759768070944e-18 0.0039999999999999992159 -0.02834999999999999673" rpy="0 -0 0" />
            <geometry>
            <mesh filename="../meshes/digit_bottom.stl"/>
            </geometry>
        </collision>
        <visual>
            <origin xyz="-1.7347234759768070944e-18 0.0039999999999999992159 -0.02834999999999999673" rpy="0 -0 0" />
            <geometry>
            <mesh filename="../meshes/digit_top.stl"/>
            </geometry>
            <material name="digit_top_material">
            <color rgba="0.30196078431372547213 0.30196078431372547213 0.30196078431372547213 1.0"/>
            </material>
        </visual>
        <collision>
            <origin xyz="-1.7347234759768070944e-18 0.0039999999999999992159 -0.02834999999999999673" rpy="0 -0 0" />
            <geometry>
            <mesh filename="../meshes/digit_top.stl"/>
            </geometry>
        </collision>
        <visual>
            <origin xyz="6.9388939039072283776e-18 0.0054726271455009002642 -0.02834999999999999673" rpy="0 -0 0" />
            <geometry>
            <mesh filename="../meshes/acrylic_window.stl"/>
            </geometry>
            <material name="acrylic_window_material">
            <color rgba="0.91764705882352937127 0.91764705882352937127 0.91764705882352937127 1.0"/>
            </material>
        </visual>
        <collision>
            <origin xyz="6.9388939039072283776e-18 0.0054726271455009002642 -0.02834999999999999673" rpy="0 -0 0" />
            <geometry>
            <mesh filename="../meshes/acrylic_window.stl"/>
            </geometry>
        </collision>
        <visual>
            <origin xyz="-1.7347234759768070944e-18 0.0039999999999999992159 -0.02834999999999999673" rpy="0 -0 0" />
            <geometry>
            <mesh filename="../meshes/digit_center.stl"/>
            </geometry>
            <material name="digit_center_material">
            <color rgba="0.30196078431372547213 0.30196078431372547213 0.30196078431372547213 1.0"/>
            </material>
        </visual>
        <collision>
            <origin xyz="-1.7347234759768070944e-18 0.0039999999999999992159 -0.02834999999999999673" rpy="0 -0 0" />
            <geometry>
            <mesh filename="../meshes/digit_center.stl"/>
            </geometry>
        </collision>
        <inertial>
            <origin xyz="5.63455410584598546e-09 -0.00036102000365889093522 -0.017219651141187425347" rpy="0 0 0"/>
            <mass value="0.011198578791898805909" />
            <inertia ixx="1.9644553798333779512e-06" ixy="-2.4770919459996182574e-12"  ixz="1.0361463195467100313e-11" iyy="1.6079833449569471555e-06" iyz="3.8106738589359573195e-09" izz="1.878363607520652625e-06" />
        </inertial>
    </link>

    <joint name="world_digit" type="fixed">
        <origin xyz="0 0 0" rpy="0 0 0" />
        <parent link="world" />
        <child link="digit_base" />
        <axis xyz="0 0 0"/>
    </joint>

    <link name="gel">
        <fem>
        <origin xyz="3.4694469519536141888e-18 0.005472545706442896 -0.0242" rpy="0 3.141592653589793116 0" />
        <density value="1e3"/>
        <youngs value="1e6"/>
        <poissons value="0.3"/>
        <damping value="0.0"/>

        <!-- Soft body trembles for unknown reasons. TODO -->
        <attachDistance value="1.0e-3"/>
        
        <tetmesh filename="../meshes/gel.tet"/>
        </fem>
    </link>

    <joint name="attach" type="fixed">
        <origin xyz="0 0 0" rpy="0 0 0" />
        <parent link="digit_base" />
        <child link="gel" />
        <axis xyz="0 0 0"/>
    </joint>

    <!-- <link name="gel">
        <visual>
            <origin xyz="0 -0.017265197057134345354 0.0041499999999999974409" rpy="3.141592653589793116 -0 0" />
            <geometry>
            <mesh filename="../meshes/gel.stl"/>
            </geometry>
            <material name="gel_material">
            <color rgba="1 1 1 1.0"/>
            </material>
        </visual>
        <collision>
            <origin xyz="0 -0.017265197057134345354 0.0041499999999999974409" rpy="3.141592653589793116 -0 0" />
            <geometry>
            <mesh filename="../meshes/gel.stl"/>
            </geometry>
        </collision>
        <inertial>
            <origin xyz="-8.5602937331140888203e-07 -0.011723770481359294116 -0.0016105116766832513336" rpy="0 0 0"/>
            <mass value="0.0014345905870518961545" />
            <inertia ixx="6.0313927889399397696e-08" ixy="4.7367407930572109158e-12"  ixz="-2.9117704751932360282e-13" iyy="3.3418770542100367402e-08" iyz="-1.7264897120244444177e-10" izz="9.0887399872856152826e-08" />
        </inertial>
    </link> -->

    <!-- <joint name="attach" type="fixed">
        <origin xyz="3.4694469519536141888e-18 -0.011792651350691449319 -0.02834999999999999673" rpy="0 -0 3.141592653589793116" />
        <parent link="digit_base" />
        <child link="gel" />
        <axis xyz="0 0 1"/>
        <limit effort="1" velocity="20" />
        <joint_properties friction="0.0"/>
    </joint> -->

</robot>
